例14.2 在函数嵌套的情况下检测异常处理。
这是一个简单的例子，用来说明在try块中有函数嵌套调用的情况下抛出异常和捕捉异常的情况。请自己先分析以下程序。
#include <iostream>
using namespace std;
int main( )
{void f1( );
 try
  {f1( );}//调用f1( )
 catch(double)
  {cout<<″OK0!″<<endl;}
 cout<<″end0″<<endl;
 return 0;
}
void f1( )
{void f2( );
 try
  {f2( );}                      //调用f2( )
 catch(char)
  {cout<<″OK1!″;}
 cout<<″end1″<<endl;
}

void f2( )
{void f3( );
 try
 {f3( );}                      //调用f3( )
 catch(int)
 {cout<<″Ok2!″<<endl;}
 cout<<″end2″<<endl;
}
void f3( )
{double a=0;
 try 
  {throw a;}               //抛出double类型异常信息
 catch(float)
  {cout<<″OK3!″<<endl;}
 cout<<″end3″<<endl;
}